<?xml version="1.0" encoding="utf-8"?>

<robot name="ur10" xmlns:xacro="http://wiki.ros.org/xacro">
    <!-- measured from model -->
    <link name="base_link">
        <visual>
            <geometry>
                <mesh filename="package://visual/base.dae" />
            </geometry>
            <material name="LightGrey">
                <color rgba="0.7 0.7 0.7 1.0" />
            </material>
        </visual>
        <collision>
            <geometry>
                <mesh filename="package://collision/base.stl" />
            </geometry>
        </collision>
        <inertial>
            <mass value="4.0" />
            <origin rpy="0 0 0" xyz="0.0 0.0 0.0" />
            <inertia ixx="0.0061063308908" ixy="0.0" ixz="0.0" iyy="0.0061063308908" iyz="0.0"
                izz="0.01125" />
        </inertial>
    </link>
    <joint name="shoulder_pan_joint"
        type="revolute">
        <parent link="base_link" />
        <child link="shoulder_link" />
        <origin rpy="0.0 0.0 0.0" xyz="0.0 0.0 0.1273" />
        <axis xyz="0 0 1" />
        <limit effort="330.0" lower="-6.28318530718" upper="6.28318530718" velocity="2.16" />
        <dynamics damping="0.0" friction="0.0" />
    </joint>
    <link name="shoulder_link">
        <visual>
            <geometry>
                <mesh filename="package://visual/shoulder.dae" />
            </geometry>
            <material name="LightGrey">
                <color rgba="0.7 0.7 0.7 1.0" />
            </material>
        </visual>
        <collision>
            <geometry>
                <mesh filename="package://collision/shoulder.stl" />
            </geometry>
        </collision>
        <inertial>
            <mass value="7.778" />
            <origin rpy="0 0 0" xyz="0.0 0.0 0.0" />
            <inertia ixx="0.0314743125769" ixy="0.0" ixz="0.0" iyy="0.0314743125769" iyz="0.0"
                izz="0.021875625" />
        </inertial>
    </link>
    <joint name="shoulder_lift_joint"
        type="revolute">
        <parent link="shoulder_link" />
        <child link="upper_arm_link" />
        <origin rpy="0.0 1.57079632679 0.0" xyz="0.0 0.220941 0.0" />
        <axis xyz="0 1 0" />
        <limit effort="330.0" lower="-6.28318530718" upper="6.28318530718" velocity="2.16" />
        <dynamics damping="0.0" friction="0.0" />
    </joint>
    <link name="upper_arm_link">
        <visual>
            <geometry>
                <mesh filename="package://visual/upperarm.dae" />
            </geometry>
            <material name="LightGrey">
                <color rgba="0.7 0.7 0.7 1.0" />
            </material>
        </visual>
        <collision>
            <geometry>
                <mesh filename="package://collision/upperarm.stl" />
            </geometry>
        </collision>
        <inertial>
            <mass value="12.93" />
            <origin rpy="0 0 0" xyz="0.0 0.0 0.306" />
            <inertia ixx="0.421753803798" ixy="0.0" ixz="0.0" iyy="0.421753803798" iyz="0.0"
                izz="0.036365625" />
        </inertial>
    </link>
    <joint name="elbow_joint"
        type="revolute">
        <parent link="upper_arm_link" />
        <child link="forearm_link" />
        <origin rpy="0.0 0.0 0.0" xyz="0.0 -0.1719 0.612" />
        <axis xyz="0 1 0" />
        <limit effort="150.0" lower="-3.14159265359" upper="3.14159265359" velocity="3.15" />
        <dynamics damping="0.0" friction="0.0" />
    </joint>
    <link name="forearm_link">
        <visual>
            <geometry>
                <mesh filename="package://visual/forearm.dae" />
            </geometry>
            <material name="LightGrey">
                <color rgba="0.7 0.7 0.7 1.0" />
            </material>
        </visual>
        <collision>
            <geometry>
                <mesh filename="package://collision/forearm.stl" />
            </geometry>
        </collision>
        <inertial>
            <mass value="3.87" />
            <origin rpy="0 0 0" xyz="0.0 0.0 0.28615" />
            <inertia ixx="0.111069694097" ixy="0.0" ixz="0.0" iyy="0.111069694097" iyz="0.0"
                izz="0.010884375" />
        </inertial>
    </link>
    <joint name="wrist_1_joint"
        type="revolute">
        <parent link="forearm_link" />
        <child link="wrist_1_link" />
        <origin rpy="0.0 1.57079632679 0.0" xyz="0.0 0.0 0.5723" />
        <axis xyz="0 1 0" />
        <limit effort="54.0" lower="-6.28318530718" upper="6.28318530718" velocity="3.2" />
        <dynamics damping="0.0" friction="0.0" />
    </joint>
    <link name="wrist_1_link">
        <visual>
            <geometry>
                <mesh filename="package://visual/wrist1.dae" />
            </geometry>
            <material name="LightGrey">
                <color rgba="0.7 0.7 0.7 1.0" />
            </material>
        </visual>
        <collision>
            <geometry>
                <mesh filename="package://collision/wrist1.stl" />
            </geometry>
        </collision>
        <inertial>
            <mass value="1.96" />
            <origin rpy="0 0 0" xyz="0.0 0.0 0.0" />
            <inertia ixx="0.0051082479567" ixy="0.0" ixz="0.0" iyy="0.0051082479567" iyz="0.0"
                izz="0.0055125" />
        </inertial>
    </link>
    <joint name="wrist_2_joint"
        type="revolute">
        <parent link="wrist_1_link" />
        <child link="wrist_2_link" />
        <origin rpy="0.0 0.0 0.0" xyz="0.0 0.1149 0.0" />
        <axis xyz="0 0 1" />
        <limit effort="54.0" lower="-6.28318530718" upper="6.28318530718" velocity="3.2" />
        <dynamics damping="0.0" friction="0.0" />
    </joint>
    <link name="wrist_2_link">
        <visual>
            <geometry>
                <mesh filename="package://visual/wrist2.dae" />
            </geometry>
            <material name="LightGrey">
                <color rgba="0.7 0.7 0.7 1.0" />
            </material>
        </visual>
        <collision>
            <geometry>
                <mesh filename="package://collision/wrist2.stl" />
            </geometry>
        </collision>
        <inertial>
            <mass value="1.96" />
            <origin rpy="0 0 0" xyz="0.0 0.0 0.0" />
            <inertia ixx="0.0051082479567" ixy="0.0" ixz="0.0" iyy="0.0051082479567" iyz="0.0"
                izz="0.0055125" />
        </inertial>
    </link>
    <joint name="wrist_3_joint"
        type="revolute">
        <parent link="wrist_2_link" />
        <child link="wrist_3_link" />
        <origin rpy="0.0 0.0 0.0" xyz="0.0 0.0 0.1157" />
        <axis xyz="0 1 0" />
        <limit effort="54.0" lower="-6.28318530718" upper="6.28318530718" velocity="3.2" />
        <dynamics damping="0.0" friction="0.0" />
    </joint>
    <link name="wrist_3_link">
        <visual>
            <geometry>
                <mesh filename="package://visual/wrist3.dae" />
            </geometry>
            <material name="LightGrey">
                <color rgba="0.7 0.7 0.7 1.0" />
            </material>
        </visual>
        <collision>
            <geometry>
                <mesh filename="package://collision/wrist3.stl" />
            </geometry>
        </collision>
        <inertial>
            <mass value="0.202" />
            <origin rpy="0 0 0" xyz="0.0 0.0 0.0" />
            <inertia ixx="0.000526462289415" ixy="0.0" ixz="0.0" iyy="0.000526462289415" iyz="0.0"
                izz="0.000568125" />
        </inertial>
    </link>
    <joint name="ee_fixed_joint"
        type="fixed">
        <parent link="wrist_3_link" />
        <child link="ee_link" />
        <origin rpy="0.0 0.0 1.57079632679" xyz="0.0 0.0922 0.0" />
    </joint>
    <link name="ee_link">
        <collision>
            <geometry>
                <box size="0.01 0.01 0.01" />
            </geometry>
            <origin rpy="0 0 0" xyz="-0.01 0 0" />
        </collision>
        <inertial>
            <mass value="0.0" />
            <origin rpy="0 0 0" xyz="0 0 0" />
            <inertia ixx="0.0" ixy="0.0" ixz="0.0" iyy="0.0" iyz="0.0" izz="0.0" />
        </inertial>
    </link>


    <link name="world" />
    <joint name="world_joint" type="fixed">
        <parent link="world" />
        <child link="base_link" />
        <origin rpy="0.0 0.0 0.0" xyz="0.0 0.0 0.0" />
    </joint>

    <joint name="tool_joint" type="fixed">
        <origin rpy="0 0 0" xyz="0 0 0" />
        <parent link="ee_link" />
        <child link="tool_link" />
    </joint>
    <link name="tool_link">
        <visual>
            <geometry>
                <mesh filename="package://hoop_ring.stl" scale=".001 .001 .001" />
            </geometry>
            <material name="gray">
                <color rgba="0.4 0.4 0.4 1" />
            </material>
        </visual>
        <collision>
            <geometry>
                <mesh filename="package://hoop_ring.stl" scale=".001 .001 .001" />
            </geometry>
        </collision>
    </link>

    <link name="tcp" />
    <joint name="tcp_joint" type="fixed">
        <origin rpy="0 -1.57079632679 0" xyz="-0.01 0 0.22" />
        <parent link="tool_link" />
        <child link="tcp" />
    </joint>
    <joint name="table_joint" type="fixed">
        <origin rpy="0.0 0.0 0.0" xyz="0 0 0" />
        <parent link="world" />
        <child link="table_link" />
    </joint>
    <link name="table_link">
        <visual>
            <origin xyz="0.500 0. 0" />
            <geometry>
                <box size="1.580 0.840 0.025" />
            </geometry>
            <material name="LightGrey2">
                <color rgba="0.8 0.8 0.8 1.0" />
            </material>
        </visual>
    </link>
</robot>